Workbook

Sheet Carbon footprint calculator
V5: Carbon footprint [kgCO2equ/FU] | W5: Gasoline car | X5: Electric car - Hard coal | Y5: Electric car electricity mix | Z5: Electric car - Wind | AA5: Electric car - Photovoltaic | AB5: E-bike - electricity mix | AC5: Conventional bike | AF5: Human health [min. lost/FU] | AG5: Gasoline car | AH5: Electric car - Hard coal | AI5: Electric car electricity mix | AJ5: Electric car - Wind | AK5: Electric car - Photovoltaic | AL5: E-bike - electricity mix | AM5: Conventional bike | AO5: Ecosystem quality impacts [species-yr/FU] | AP5: Gasoline car | AQ5: Electric car - Hard coal | AR5: Electric car electricity mix | AS5: Electric car - Wind | AT5: Electric car - Photovoltaic | AU5: E-bike - electricity mix | AV5: Conventional bike | AX5: Cumulative energy demand [MJ/FU] | AY5: Gasoline car | AZ5: Electric car - Hard coal | BA5: Electric car electricity mix | BB5: Electric car - Wind | BC5: Electric car - Photovoltaic | BD5: E-bike - electricity mix | BE5: Conventional bike
V6: Manufacturing & raw materials | W6: =SUM(I23:I35) -> 0.032727847 | X6: =SUM($I$56:$I$70) -> 0.046491543 | Y6: =SUM($I$56:$I$70) -> 0.046491543 | Z6: =SUM($I$56:$I$70) -> 0.046491543 | AA6: =SUM($I$56:$I$70) -> 0.046491543 | AB6: =SUM(I98:I99) -> 0.0048466754 | AC6: =SUM(I119:I120) -> 0.0048466754 | AF6: =V6 -> Manufacturing & raw materials | AG6: =SUM(L23:L35) -> 0.088065815 | AH6: =SUM($L$56:$L$70) -> 0.12515818 | AI6: =SUM($L$56:$L$70) -> 0.12515818 | AJ6: =SUM($L$56:$L$70) -> 0.12515818 | AK6: =SUM($L$56:$L$70) -> 0.12515818 | AL6: =SUM($L$98:$L$99) -> 0.01145343 | AM6: =SUM(L119:L120) -> 0.01145343 | AO6: =AF6 -> Manufacturing & raw materials | AP6: =SUM(O23:O35) -> 1.5987586e-10 | AQ6: =SUM($O$56:$O$70) -> 2.7067631e-10 | AR6: =SUM($O$56:$O$70) -> 2.7067631e-10 | AS6: =SUM($O$56:$O$70) -> 2.7067631e-10 | AT6: =SUM($O$56:$O$70) -> 2.7067631e-10 | AU6: =SUM($O98:$O99) -> 2.2519353e-11 | AV6: =AU6 -> 2.2519353e-11 | AX6: =AF6 -> Manufacturing & raw materials | AY6: =SUM(R23:R35) -> 0.56786645 | AZ6: =SUM($R$56:$R$70) -> 0.71482272 | BA6: =SUM($R$56:$R$70) -> 0.71482272 | BB6: =SUM($R$56:$R$70) -> 0.71482272 | BC6: =SUM($R$56:$R$70) -> 0.71482272 | BD6: =SUM($R98:$R99) -> 0.056742791 | BE6: =SUM($R98:$R99) -> 0.056742791
V7: Transportation | W7: =SUM(I37:I39) -> 0.001015679 | X7: =SUM($I$72:$I$74) -> 0.0005938773 | Y7: =SUM($I$72:$I$74) -> 0.0005938773 | Z7: =SUM($I$72:$I$74) -> 0.0005938773 | AA7: =SUM($I$72:$I$74) -> 0.0005938773 | AB7: =SUM(I101:I103) -> 0.00030603795 | AC7: =SUM(I122:I124) -> 0.00024160891 | AF7: =V7 -> Transportation | AG7: =SUM(L37:L39) -> 0.0023378932 | AH7: =SUM($L$72:$L$74) -> 0.0013419962 | AI7: =SUM($L$72:$L$74) -> 0.0013419962 | AJ7: =SUM($L$72:$L$74) -> 0.0013419962 | AK7: =SUM($L$72:$L$74) -> 0.0013419962 | AL7: =SUM($L$72:$L$74) -> 0.0013419962 | AM7: =SUM(L122:L124) -> 0.00033331625 | AO7: =AF7 -> Transportation | AP7: =SUM(O37:O39) -> 8.5706313e-12 | AQ7: =SUM($O$72:$O$74) -> 4.9267156e-12 | AR7: =SUM($O$72:$O$74) -> 4.9267156e-12 | AS7: =SUM($O$72:$O$74) -> 4.9267156e-12 | AT7: =SUM($O$72:$O$74) -> 4.9267156e-12 | AU7: =SUM($O101:$O103) -> 1.7205772e-12 | AV7: =AU7 -> 1.7205772e-12 | AX7: =AF7 -> Transportation | AY7: =SUM(R37:R39) -> 0.013882458 | AZ7: =SUM($R$72:$R$74) -> 0.0081645564 | BA7: =SUM($R$72:$R$74) -> 0.0081645564 | BB7: =SUM($R$72:$R$74) -> 0.0081645564 | BC7: =SUM($R$72:$R$74) -> 0.0081645564 | BD7: =SUM($R101:$R103) -> 0.0045043097 | BE7: =SUM($R101:$R103) -> 0.0045043097
V8: Disposal | W8: =SUM(I45:I47) -> 0.0017928846 | X8: =SUM($I$82:$I$85) -> 0.0020882669 | Y8: =SUM($I$82:$I$85) -> 0.0020882669 | Z8: =SUM($I$82:$I$85) -> 0.0020882669 | AA8: =SUM($I$82:$I$85) -> 0.0020882669 | AB8: =SUM(I108:I108) -> 7.8191141e-05 | AC8: =SUM(I129:I129) -> 7.8191141e-05 | AF8: =V8 -> Disposal | AG8: =SUM(L45:L47) -> -0.00018269536 | AH8: =SUM($L$82:$L$85) -> -0.00022737211 | AI8: =SUM($L$82:$L$85) -> -0.00022737211 | AJ8: =SUM($L$82:$L$85) -> -0.00022737211 | AK8: =SUM($L$82:$L$85) -> -0.00022737211 | AL8: =SUM($L$82:$L$85) -> -0.00022737211 | AM8: =SUM(L129:L129) -> 4.3717805e-05 | AO8: =AF8 -> Disposal | AP8: =SUM(O45:O47) -> 2.114838e-12 | AQ8: =SUM($O$82:$O$85) -> 2.407329e-12 | AR8: =SUM($O$82:$O$85) -> 2.407329e-12 | AS8: =SUM($O$82:$O$85) -> 2.407329e-12 | AT8: =SUM($O$82:$O$85) -> 2.407329e-12 | AU8: =SUM($O108:$O108) -> 2.2644518e-13 | AV8: =AU8 -> 2.2644518e-13 | AX8: =AF8 -> Disposal | AY8: =SUM(R45:R47) -> -0.037620082 | AZ8: =SUM($R$82:$R$85) -> -0.044361663 | BA8: =SUM($R$82:$R$85) -> -0.044361663 | BB8: =SUM($R$82:$R$85) -> -0.044361663 | BC8: =SUM($R$82:$R$85) -> -0.044361663 | BD8: =SUM($R108:$R108) -> 1.6240435e-05 | BE8: =SUM($R108:$R108) -> 1.6240435e-05
V9: Vehicle use | W9: =SUM(I42:I43) -> 0.27505153 | AF9: =V9 -> Vehicle use | AG9: =SUM(L42:L43) -> 0.3485735 | AO9: =AF9 -> Vehicle use | AP9: =SUM(O42:O43) -> 1.3568873e-09 | AX9: =AF9 -> Vehicle use | AY9: =SUM(R42:R43) -> 3.5141563
V10: Vehicle physical activity | AF10: =V10 -> Vehicle physical activity | AG10: =L41 -> -0.72627994 | AH10: =L76 -> -0.72627994 | AI10: =L76 -> -0.72627994 | AJ10: =L76 -> -0.72627994 | AK10: =L76 -> -0.72627994 | AL10: =L105 -> -6.2175665 | AM10: =L126 -> -9.3263497 | AO10: =AF10 -> Vehicle physical activity | AX10: =AF10 -> Vehicle physical activity
V11: Electric charging - EU | Y11: =I77 -> 0.10008312 | AB11: =SUM(I105:I106) -> 0.0026945455 | AC11: =SUM(I126:I127) -> 0 | AF11: Electric charging - EU | AI11: =L77 -> 0.12722285 | AL11: =L106 -> 0.0034252306 | AM11: =L127 -> 0 | AO11: Electric charging - EU | AR11: =O77 -> 4.7592494e-10 | AU11: =SUM(O105:O106) -> 1.2813364e-11 | AV11: 0 | AX11: Electric charging - EU | BA11: =R77 -> 2.3097052 | BD11: =SUM(R105:R106) -> 0.062184371 | BE11: 0
V12: Electric charging - wind | Z12: =I78 -> 0.0038344612 | AF12: Electric charging - wind | AJ12: =L78 -> 0.010658041 | AO12: Electric charging - wind | AS12: =O78 -> 2.1501693e-11 | AX12: Electric charging - wind | BB12: =R78 -> 0.052025962
V13: Electric charging - photovoltaic | AA13: =I79 -> 0.020865159 | AF13: Electric charging - photovoltaic | AK13: =L79 -> 0.038374462 | AO13: Electric charging - photovoltaic | AT13: =O79 -> 1.7005097e-10 | AX13: Electric charging - photovoltaic | BC13: =R79 -> 0.27552472
V14: Electric charging - hard coal | X14: =I80 -> 0.28483847 | AF14: Electric charging - hard coal | AH14: =L80 -> 0.42919009 | AO14: Electric charging - hard coal | AQ14: =O80 -> 1.5018117e-09 | AX14: Electric charging - hard coal | AZ14: =R80 -> 2.9354912
V15: Net value | W15: =SUM(W6:W14) -> 0.31058794 | X15: =SUM(X6:X14) -> 0.33401216 | Y15: =SUM(Y6:Y11) -> 0.14925681 | Z15: =SUM(Z6:Z14) -> 0.053008148 | AA15: =SUM(AA6:AA14) -> 0.070038846 | AB15: =SUM(AB6:AB14) -> 0.00792545 | AC15: =SUM(AC6:AC14) -> 0.0051664754 | AF15: Net value | AG15: =SUM(AG6:AG14) -> -0.28748543 | AH15: =SUM(AH6:AH14) -> -0.17081706 | AI15: =SUM(AI6:AI14) -> -0.47278429 | AJ15: =SUM(AJ6:AJ14) -> -0.5893491 | AK15: =SUM(AK6:AK14) -> -0.56163268 | AL15: =SUM(AL6:AL14) -> -6.2015732 | AM15: =SUM(AM6:AM14) -> -9.3145193 | AO15: Net value | AP15: =SUM(AP6:AP9) -> 1.5274486e-09 | AQ15: =SUM(AQ6:AQ14) -> 1.7798221e-09 | AR15: =SUM(AR6:AR11) -> 7.5393529e-10 | AS15: =SUM(AS6:AS8, AS12) -> 2.9951205e-10 | AT15: =SUM(AT6:AT14) -> 4.4806132e-10 | AU15: =SUM(AU6:AU14) -> 3.7279739e-11 | AV15: =SUM(AV6:AV14) -> 2.4466376e-11 | AX15: Net value | AY15: =SUM(AY6:AY9) -> 4.0582852 | AZ15: =SUM(AZ6:AZ14) -> 3.6141168 | BA15: =SUM(BA6:BA11) -> 2.9883308 | BB15: =SUM(BB6:BB8, BB12) -> 0.73065158 | BC15: =SUM(BC6:BC14) -> 0.95415034 | BD15: =SUM(BD6:BD14) -> 0.12344771 | BE15: =SUM(BE6:BE14) -> 0.061263341
A17: kg/t conversion factor | B17: 1000 | C17: Energy recovery from paper | E17: 42.5 | F17: MJ/kg
A18: g/kg, Wh/kWh | B18: 1000 | C18: Conversion efficiency | E18: 0.25
C19: Conversion factor | E19: 3.6 | F19: MJ/kWh
B20: Vehicle lifespan (km/vehicle) | C20: 150000
A21: Process # | B21: Transportation by Gas Vehicle Functional unit (FU)= 1 vehicle km Life Cycle stage (150,000 km lifespan) | C21: Ecoinvent process | D21: Region | E21: Quantity original unit | F21: Quantity per FU | G21: Unit | H21: Carbon footprint [kgCO2equ/unit] | I21: Carbon footprint [CO2equ./FU] | J21: fraction carbon footprint | K21: Human health/Unit [min. lost/unit] | L21: Human health [min. lost/FU] | M21: fraction human health | N21: Ecosystem quality impacts/Unit [species-yr/unit] | O21: Ecosystem quality impacts [Species-yr/FU] | P21: fraction ecosystem quality | Q21: Non renewable primary energy resources/unit [MJ/unit] | R21: Non renewable primary energy resources impacts [MJ/FU] | S21: fraction non renewable primary energy | T21: Check [gCO2e/MJ]
B22: Manufacturing (Materials + Processing) | C22: Manufacturing (Materials + Processing) | E22: per vehicle over lifespan | F22: per FU
A23: 17299 | B23: steel, low-alloyed, hot rolled | C23: =INDEX('Selected processes'!$E$5:$E$97, MATCH('Carbon footprint calculator'!$A23,'Selected processes'!$D$5:$D$97,0)) -> steel production, low-alloyed, hot rolled | D23: =INDEX('Selected processes'!$F$5:$F$97, MATCH('Carbon footprint calculator'!$A23,'Selected processes'!$D$5:$D$97,0)) -> RER | E23: 1040 | F23: =E23/$C$20 -> 0.0069333333 | G23: =INDEX('Selected processes'!$H$5:$H$97, MATCH('Carbon footprint calculator'!$A23,'Selected processes'!$D$5:$D$97,0)) -> kg | H23: =INDEX('Selected processes'!$J$5:$J$97, MATCH('Carbon footprint calculator'!$A23,'Selected processes'!$D$5:$D$97,0)) -> 2.1807172 | I23: =H23*$F23 -> 0.01511964 | J23: =I23/I$49 -> 0.048680705 | K23: =INDEX('Selected processes'!$K$5:$K$97, MATCH('Carbon footprint calculator'!$A23,'Selected processes'!$D$5:$D$97,0)) -> 7.9963289 | L23: =K23*$F23 -> 0.055441214 | M23: =L23/L$49 -> -0.19284878 | N23: =INDEX('Selected processes'!$L$5:$L$97, MATCH('Carbon footprint calculator'!$A23,'Selected processes'!$D$5:$D$97,0)) -> 9.7808189e-09 | O23: =N23*$F23 -> 6.7813678e-11 | P23: =O23/O$49 -> 0.0443967 | Q23: =INDEX('Selected processes'!$N$5:$N$97, MATCH('Carbon footprint calculator'!$A23,'Selected processes'!$D$5:$D$97,0)) -> 25.556652 | R23: =Q23*$F23 -> 0.17719279 | S23: =R23/R$49 -> 0.043661986 | T23: =I23/R23*$B$18 -> 85.328752
A24: 16619 | B24: sheet rolling, steel | C24: =INDEX('Selected processes'!$E$5:$E$97, MATCH('Carbon footprint calculator'!$A24,'Selected processes'!$D$5:$D$97,0)) -> sheet rolling, steel | D24: =INDEX('Selected processes'!$F$5:$F$97, MATCH('Carbon footprint calculator'!$A24,'Selected processes'!$D$5:$D$97,0)) -> RER | E24: 780 | F24: =E24/$C$20 -> 0.0052 | G24: =INDEX('Selected processes'!$H$5:$H$97, MATCH('Carbon footprint calculator'!$A24,'Selected processes'!$D$5:$D$97,0)) -> kg | H24: =INDEX('Selected processes'!$J$5:$J$97, MATCH('Carbon footprint calculator'!$A24,'Selected processes'!$D$5:$D$97,0)) -> 0.31200613 | I24: =H24*$F24 -> 0.0016224319 | J24: =I24/I$49 -> 0.005223744 | K24: =INDEX('Selected processes'!$K$5:$K$97, MATCH('Carbon footprint calculator'!$A24,'Selected processes'!$D$5:$D$97,0)) -> 0.73372079 | L24: =K24*$F24 -> 0.0038153481 | M24: =L24/L$49 -> -0.013271449 | N24: =INDEX('Selected processes'!$L$5:$L$97, MATCH('Carbon footprint calculator'!$A24,'Selected processes'!$D$5:$D$97,0)) -> 1.3767966e-09 | O24: =N24*$F24 -> 7.1593425e-12 | P24: =O24/O$49 -> 0.0046871249 | Q24: =INDEX('Selected processes'!$N$5:$N$97, MATCH('Carbon footprint calculator'!$A24,'Selected processes'!$D$5:$D$97,0)) -> 4.9309388 | R24: =Q24*$F24 -> 0.025640882 | S24: =R24/R$49 -> 0.0063181567 | T24: =I24/R24*$B$18 -> 63.275198
A25: 458 | B25: aluminium, primary, ingot | C25: =INDEX('Selected processes'!$E$5:$E$97, MATCH('Carbon footprint calculator'!$A25,'Selected processes'!$D$5:$D$97,0)) -> aluminium production, primary, ingot | D25: =INDEX('Selected processes'!$F$5:$F$97, MATCH('Carbon footprint calculator'!$A25,'Selected processes'!$D$5:$D$97,0)) -> IAI Area, EU27 & EFTA | E25: 55 | F25: =E25/$C$20 -> 0.00036666667 | G25: =INDEX('Selected processes'!$H$5:$H$97, MATCH('Carbon footprint calculator'!$A25,'Selected processes'!$D$5:$D$97,0)) -> kg | H25: =INDEX('Selected processes'!$J$5:$J$97, MATCH('Carbon footprint calculator'!$A25,'Selected processes'!$D$5:$D$97,0)) -> 7.209838 | I25: =H25*$F25 -> 0.0026436073 | J25: =I25/I$49 -> 0.0085116225 | K25: =INDEX('Selected processes'!$K$5:$K$97, MATCH('Carbon footprint calculator'!$A25,'Selected processes'!$D$5:$D$97,0)) -> 13.333429 | L25: =K25*$F25 -> 0.004888924 | M25: =L25/L$49 -> -0.017005815 | N25: =INDEX('Selected processes'!$L$5:$L$97, MATCH('Carbon footprint calculator'!$A25,'Selected processes'!$D$5:$D$97,0)) -> 3.2653298e-08 | O25: =N25*$F25 -> 1.1972876e-11 | P25: =O25/O$49 -> 0.0078384802 | Q25: =INDEX('Selected processes'!$N$5:$N$97, MATCH('Carbon footprint calculator'!$A25,'Selected processes'!$D$5:$D$97,0)) -> 115.04046 | R25: =Q25*$F25 -> 0.042181504 | S25: =R25/R$49 -> 0.010393923 | T25: =I25/R25*$B$18 -> 62.672192
A26: 16616 | B26: Copper & other metals (Zn, Ni, Pb) | C26: =INDEX('Selected processes'!$E$5:$E$97, MATCH('Carbon footprint calculator'!$A26,'Selected processes'!$D$5:$D$97,0)) -> sheet rolling, copper | D26: =INDEX('Selected processes'!$F$5:$F$97, MATCH('Carbon footprint calculator'!$A26,'Selected processes'!$D$5:$D$97,0)) -> RER | E26: 38 | F26: =E26/$C$20 -> 0.00025333333 | G26: =INDEX('Selected processes'!$H$5:$H$97, MATCH('Carbon footprint calculator'!$A26,'Selected processes'!$D$5:$D$97,0)) -> kg | H26: =INDEX('Selected processes'!$J$5:$J$97, MATCH('Carbon footprint calculator'!$A26,'Selected processes'!$D$5:$D$97,0)) -> 0.48163006 | I26: =H26*$F26 -> 0.00012201295 | J26: =I26/I$49 -> 0.0003928451 | K26: =INDEX('Selected processes'!$K$5:$K$97, MATCH('Carbon footprint calculator'!$A26,'Selected processes'!$D$5:$D$97,0)) -> 4.9624408 | L26: =K26*$F26 -> 0.0012571517 | M26: =L26/L$49 -> -0.0043729231 | N26: =INDEX('Selected processes'!$L$5:$L$97, MATCH('Carbon footprint calculator'!$A26,'Selected processes'!$D$5:$D$97,0)) -> 9.7940056e-09 | O26: =N26*$F26 -> 2.4811481e-12 | P26: =O26/O$49 -> 0.0016243742 | Q26: =INDEX('Selected processes'!$N$5:$N$97, MATCH('Carbon footprint calculator'!$A26,'Selected processes'!$D$5:$D$97,0)) -> 7.1938644 | R26: =Q26*$F26 -> 0.0018224456 | S26: =R26/R$49 -> 0.00044906791 | T26: =I26/R26*$B$18 -> 66.950117
A27: 12456 | B27: platinum | C27: =INDEX('Selected processes'!$E$5:$E$97, MATCH('Carbon footprint calculator'!$A27,'Selected processes'!$D$5:$D$97,0)) -> platinum to generic market for metal catalyst for catalytic converter | D27: =INDEX('Selected processes'!$F$5:$F$97, MATCH('Carbon footprint calculator'!$A27,'Selected processes'!$D$5:$D$97,0)) -> GLO | E27: 0.0017 | F27: =E27/$C$20 -> 1.1333333e-08 | G27: =INDEX('Selected processes'!$H$5:$H$97, MATCH('Carbon footprint calculator'!$A27,'Selected processes'!$D$5:$D$97,0)) -> kg | H27: =INDEX('Selected processes'!$J$5:$J$97, MATCH('Carbon footprint calculator'!$A27,'Selected processes'!$D$5:$D$97,0)) -> 69669.936 | I27: =H27*$F27 -> 0.0007895926 | J27: =I27/I$49 -> 0.0025422514 | K27: =INDEX('Selected processes'!$K$5:$K$97, MATCH('Carbon footprint calculator'!$A27,'Selected processes'!$D$5:$D$97,0)) -> 571917.51 | L27: =K27*$F27 -> 0.0064817318 | M27: =L27/L$49 -> -0.022546297 | N27: =INDEX('Selected processes'!$L$5:$L$97, MATCH('Carbon footprint calculator'!$A27,'Selected processes'!$D$5:$D$97,0)) -> 0.0011984346 | O27: =N27*$F27 -> 1.3582258e-11 | P27: =O27/O$49 -> 0.0088921213 | Q27: =INDEX('Selected processes'!$N$5:$N$97, MATCH('Carbon footprint calculator'!$A27,'Selected processes'!$D$5:$D$97,0)) -> 1106057.2 | R27: =Q27*$F27 -> 0.012535315 | S27: =R27/R$49 -> 0.0030888206 | T27: =I27/R27*$B$18 -> 62.989451
A28: 14632 | B28: polyethylene, polypropylene & PVC | C28: =INDEX('Selected processes'!$E$5:$E$97, MATCH('Carbon footprint calculator'!$A28,'Selected processes'!$D$5:$D$97,0)) -> market for polyethylene, high density, granulate | D28: =INDEX('Selected processes'!$F$5:$F$97, MATCH('Carbon footprint calculator'!$A28,'Selected processes'!$D$5:$D$97,0)) -> GLO | E28: 175 | F28: =E28/$C$20 -> 0.0011666667 | G28: =INDEX('Selected processes'!$H$5:$H$97, MATCH('Carbon footprint calculator'!$A28,'Selected processes'!$D$5:$D$97,0)) -> kg | H28: =INDEX('Selected processes'!$J$5:$J$97, MATCH('Carbon footprint calculator'!$A28,'Selected processes'!$D$5:$D$97,0)) -> 2.3276288 | I28: =H28*$F28 -> 0.0027155669 | J28: =I28/I$49 -> 0.008743311 | K28: =INDEX('Selected processes'!$K$5:$K$97, MATCH('Carbon footprint calculator'!$A28,'Selected processes'!$D$5:$D$97,0)) -> 2.3488561 | L28: =K28*$F28 -> 0.0027403321 | M28: =L28/L$49 -> -0.0095320732 | N28: =INDEX('Selected processes'!$L$5:$L$97, MATCH('Carbon footprint calculator'!$A28,'Selected processes'!$D$5:$D$97,0)) -> 9.3798954e-09 | O28: =N28*$F28 -> 1.0943211e-11 | P28: =O28/O$49 -> 0.0071643728 | Q28: =INDEX('Selected processes'!$N$5:$N$97, MATCH('Carbon footprint calculator'!$A28,'Selected processes'!$D$5:$D$97,0)) -> 80.670316 | R28: =Q28*$F28 -> 0.094115369 | S28: =R28/R$49 -> 0.02319092 | T28: =I28/R28*$B$18 -> 28.853597
A29: 17718 | B29: synthetic rubber | C29: =INDEX('Selected processes'!$E$5:$E$97, MATCH('Carbon footprint calculator'!$A29,'Selected processes'!$D$5:$D$97,0)) -> market for synthetic rubber | D29: =INDEX('Selected processes'!$F$5:$F$97, MATCH('Carbon footprint calculator'!$A29,'Selected processes'!$D$5:$D$97,0)) -> GLO | E29: 46 | F29: =E29/$C$20 -> 0.00030666667 | G29: =INDEX('Selected processes'!$H$5:$H$97, MATCH('Carbon footprint calculator'!$A29,'Selected processes'!$D$5:$D$97,0)) -> kg | H29: =INDEX('Selected processes'!$J$5:$J$97, MATCH('Carbon footprint calculator'!$A29,'Selected processes'!$D$5:$D$97,0)) -> 2.9677534 | I29: =H29*$F29 -> 0.00091011104 | J29: =I29/I$49 -> 0.0029302846 | K29: =INDEX('Selected processes'!$K$5:$K$97, MATCH('Carbon footprint calculator'!$A29,'Selected processes'!$D$5:$D$97,0)) -> 3.7317246 | L29: =K29*$F29 -> 0.0011443956 | M29: =L29/L$49 -> -0.003980708 | N29: =INDEX('Selected processes'!$L$5:$L$97, MATCH('Carbon footprint calculator'!$A29,'Selected processes'!$D$5:$D$97,0)) -> 1.3250334e-08 | O29: =N29*$F29 -> 4.0634356e-12 | P29: =O29/O$49 -> 0.0026602765 | Q29: =INDEX('Selected processes'!$N$5:$N$97, MATCH('Carbon footprint calculator'!$A29,'Selected processes'!$D$5:$D$97,0)) -> 85.662707 | R29: =Q29*$F29 -> 0.026269897 | S29: =R29/R$49 -> 0.006473152 | T29: =I29/R29*$B$18 -> 34.644637
A30: 7943 | B30: glas | C30: =INDEX('Selected processes'!$E$5:$E$97, MATCH('Carbon footprint calculator'!$A30,'Selected processes'!$D$5:$D$97,0)) -> market for flat glass, uncoated | D30: =INDEX('Selected processes'!$F$5:$F$97, MATCH('Carbon footprint calculator'!$A30,'Selected processes'!$D$5:$D$97,0)) -> RoW | E30: 32 | F30: =E30/$C$20 -> 0.00021333333 | G30: =INDEX('Selected processes'!$H$5:$H$97, MATCH('Carbon footprint calculator'!$A30,'Selected processes'!$D$5:$D$97,0)) -> kg | H30: =INDEX('Selected processes'!$J$5:$J$97, MATCH('Carbon footprint calculator'!$A30,'Selected processes'!$D$5:$D$97,0)) -> 1.0559546 | I30: =H30*$F30 -> 0.00022527031 | J30: =I30/I$49 -> 0.00072530283 | K30: =INDEX('Selected processes'!$K$5:$K$97, MATCH('Carbon footprint calculator'!$A30,'Selected processes'!$D$5:$D$97,0)) -> 1.4484757 | L30: =K30*$F30 -> 0.00030900814 | M30: =L30/L$49 -> -0.0010748654 | N30: =INDEX('Selected processes'!$L$5:$L$97, MATCH('Carbon footprint calculator'!$A30,'Selected processes'!$D$5:$D$97,0)) -> 5.395704e-09 | O30: =N30*$F30 -> 1.1510835e-12 | P30: =O30/O$49 -> 0.00075359885 | Q30: =INDEX('Selected processes'!$N$5:$N$97, MATCH('Carbon footprint calculator'!$A30,'Selected processes'!$D$5:$D$97,0)) -> 11.947723 | R30: =Q30*$F30 -> 0.0025488475 | S30: =R30/R$49 -> 0.00062806023 | T30: =I30/R30*$B$18 -> 88.381242
A31: 7364 | B31: electronics, for control units | C31: =INDEX('Selected processes'!$E$5:$E$97, MATCH('Carbon footprint calculator'!$A31,'Selected processes'!$D$5:$D$97,0)) -> electronics production, for control units | D31: =INDEX('Selected processes'!$F$5:$F$97, MATCH('Carbon footprint calculator'!$A31,'Selected processes'!$D$5:$D$97,0)) -> RER | E31: 6.1 | F31: =E31/$C$20 -> 4.0666667e-05 | G31: =INDEX('Selected processes'!$H$5:$H$97, MATCH('Carbon footprint calculator'!$A31,'Selected processes'!$D$5:$D$97,0)) -> kg | H31: =INDEX('Selected processes'!$J$5:$J$97, MATCH('Carbon footprint calculator'!$A31,'Selected processes'!$D$5:$D$97,0)) -> 31.86483 | I31: =H31*$F31 -> 0.0012958364 | J31: =I31/I$49 -> 0.0041722046 | K31: =INDEX('Selected processes'!$K$5:$K$97, MATCH('Carbon footprint calculator'!$A31,'Selected processes'!$D$5:$D$97,0)) -> 91.052321 | L31: =K31*$F31 -> 0.0037027944 | M31: =L31/L$49 -> -0.012879938 | N31: =INDEX('Selected processes'!$L$5:$L$97, MATCH('Carbon footprint calculator'!$A31,'Selected processes'!$D$5:$D$97,0)) -> 2.0683158e-07 | O31: =N31*$F31 -> 8.4111511e-12 | P31: =O31/O$49 -> 0.0055066671 | Q31: =INDEX('Selected processes'!$N$5:$N$97, MATCH('Carbon footprint calculator'!$A31,'Selected processes'!$D$5:$D$97,0)) -> 451.55328 | R31: =Q31*$F31 -> 0.018363167 | S31: =R31/R$49 -> 0.0045248586 | T31: =I31/R31*$B$18 -> 70.567154
A32: 7587 | B32: ethylene, paints, fluids | C32: =INDEX('Selected processes'!$E$5:$E$97, MATCH('Carbon footprint calculator'!$A32,'Selected processes'!$D$5:$D$97,0)) -> ethylene production, average | D32: =INDEX('Selected processes'!$F$5:$F$97, MATCH('Carbon footprint calculator'!$A32,'Selected processes'!$D$5:$D$97,0)) -> RER | E32: 30 | F32: =E32/$C$20 -> 0.0002 | G32: =INDEX('Selected processes'!$H$5:$H$97, MATCH('Carbon footprint calculator'!$A32,'Selected processes'!$D$5:$D$97,0)) -> kg | H32: =INDEX('Selected processes'!$J$5:$J$97, MATCH('Carbon footprint calculator'!$A32,'Selected processes'!$D$5:$D$97,0)) -> 1.4469179 | I32: =H32*$F32 -> 0.00028938357 | J32: =I32/I$49 -> 0.00093172831 | K32: =INDEX('Selected processes'!$K$5:$K$97, MATCH('Carbon footprint calculator'!$A32,'Selected processes'!$D$5:$D$97,0)) -> 1.1204239 | L32: =K32*$F32 -> 0.00022408479 | M32: =L32/L$49 -> -0.00077946486 | N32: =INDEX('Selected processes'!$L$5:$L$97, MATCH('Carbon footprint calculator'!$A32,'Selected processes'!$D$5:$D$97,0)) -> 5.2741423e-09 | O32: =N32*$F32 -> 1.0548285e-12 | P32: =O32/O$49 -> 0.00069058196 | Q32: =INDEX('Selected processes'!$N$5:$N$97, MATCH('Carbon footprint calculator'!$A32,'Selected processes'!$D$5:$D$97,0)) -> 67.934853 | R32: =Q32*$F32 -> 0.013586971 | S32: =R32/R$49 -> 0.0033479585 | T32: =I32/R32*$B$18 -> 21.298609
A33: 17773 | B33: tap water | C33: =INDEX('Selected processes'!$E$5:$E$97, MATCH('Carbon footprint calculator'!$A33,'Selected processes'!$D$5:$D$97,0)) -> tap water production, conventional treatment | D33: =INDEX('Selected processes'!$F$5:$F$97, MATCH('Carbon footprint calculator'!$A33,'Selected processes'!$D$5:$D$97,0)) -> RoW | E33: 3400 | F33: =E33/$C$20 -> 0.022666667 | G33: =INDEX('Selected processes'!$H$5:$H$97, MATCH('Carbon footprint calculator'!$A33,'Selected processes'!$D$5:$D$97,0)) -> kg | H33: =INDEX('Selected processes'!$J$5:$J$97, MATCH('Carbon footprint calculator'!$A33,'Selected processes'!$D$5:$D$97,0)) -> 0.00043545824 | I33: =H33*$F33 -> 9.8703867e-06 | J33: =I33/I$49 -> 3.1779685e-05 | K33: =INDEX('Selected processes'!$K$5:$K$97, MATCH('Carbon footprint calculator'!$A33,'Selected processes'!$D$5:$D$97,0)) -> 0.00063383807 | L33: =K33*$F33 -> 1.4366996e-05 | M33: =L33/L$49 -> -4.9974694e-05 | N33: =INDEX('Selected processes'!$L$5:$L$97, MATCH('Carbon footprint calculator'!$A33,'Selected processes'!$D$5:$D$97,0)) -> 1.9288846e-12 | O33: =N33*$F33 -> 4.3721384e-14 | P33: =O33/O$49 -> 2.86238e-05 | Q33: =INDEX('Selected processes'!$N$5:$N$97, MATCH('Carbon footprint calculator'!$A33,'Selected processes'!$D$5:$D$97,0)) -> 0.0056091535 | R33: =Q33*$F33 -> 0.00012714081 | S33: =R33/R$49 -> 3.1328703e-05 | T33: =I33/R33*$B$18 -> 77.633503
A34: 9148 | B34: heat, district or industrial, natural gas | C34: =INDEX('Selected processes'!$E$5:$E$97, MATCH('Carbon footprint calculator'!$A34,'Selected processes'!$D$5:$D$97,0)) -> heat production, natural gas, at industrial furnace >100kW | D34: =INDEX('Selected processes'!$F$5:$F$97, MATCH('Carbon footprint calculator'!$A34,'Selected processes'!$D$5:$D$97,0)) -> Europe without Switzerland | E34: 2400 | F34: =E34/$C$20 -> 0.016 | G34: =INDEX('Selected processes'!$H$5:$H$97, MATCH('Carbon footprint calculator'!$A34,'Selected processes'!$D$5:$D$97,0)) -> MJ | H34: =INDEX('Selected processes'!$J$5:$J$97, MATCH('Carbon footprint calculator'!$A34,'Selected processes'!$D$5:$D$97,0)) -> 0.075656104 | I34: =H34*$F34 -> 0.0012104977 | J34: =I34/I$49 -> 0.0038974394 | K34: =INDEX('Selected processes'!$K$5:$K$97, MATCH('Carbon footprint calculator'!$A34,'Selected processes'!$D$5:$D$97,0)) -> 0.044167738 | L34: =K34*$F34 -> 0.00070668381 | M34: =L34/L$49 -> -0.0024581552 | N34: =INDEX('Selected processes'!$L$5:$L$97, MATCH('Carbon footprint calculator'!$A34,'Selected processes'!$D$5:$D$97,0)) -> 2.338698e-10 | O34: =N34*$F34 -> 3.7419167e-12 | P34: =O34/O$49 -> 0.0024497824 | Q34: =INDEX('Selected processes'!$N$5:$N$97, MATCH('Carbon footprint calculator'!$A34,'Selected processes'!$D$5:$D$97,0)) -> 1.2643686 | R34: =Q34*$F34 -> 0.020229898 | S34: =R34/R$49 -> 0.0049848388 | T34: =I34/R34*$B$18 -> 59.837064
A35: 7235 | B35: electricity, medium voltage | C35: =INDEX('Selected processes'!$E$5:$E$97, MATCH('Carbon footprint calculator'!$A35,'Selected processes'!$D$5:$D$97,0)) -> market group for electricity, medium voltage | D35: =INDEX('Selected processes'!$F$5:$F$97, MATCH('Carbon footprint calculator'!$A35,'Selected processes'!$D$5:$D$97,0)) -> UCTE | E35: 2250 | F35: =E35/$C$20 -> 0.015 | G35: =INDEX('Selected processes'!$H$5:$H$97, MATCH('Carbon footprint calculator'!$A35,'Selected processes'!$D$5:$D$97,0)) -> kWh | H35: =INDEX('Selected processes'!$J$5:$J$97, MATCH('Carbon footprint calculator'!$A35,'Selected processes'!$D$5:$D$97,0)) -> 0.38493508 | I35: =H35*$F35 -> 0.0057740262 | J35: =I35/I$49 -> 0.018590632 | K35: =INDEX('Selected processes'!$K$5:$K$97, MATCH('Carbon footprint calculator'!$A35,'Selected processes'!$D$5:$D$97,0)) -> 0.48931866 | L35: =K35*$F35 -> 0.0073397799 | M35: =L35/L$49 -> -0.025530964 | N35: =INDEX('Selected processes'!$L$5:$L$97, MATCH('Carbon footprint calculator'!$A35,'Selected processes'!$D$5:$D$97,0)) -> 1.8304805e-09 | O35: =N35*$F35 -> 2.7457208e-11 | P35: =O35/O$49 -> 0.017975863 | Q35: =INDEX('Selected processes'!$N$5:$N$97, MATCH('Carbon footprint calculator'!$A35,'Selected processes'!$D$5:$D$97,0)) -> 8.8834816 | R35: =Q35*$F35 -> 0.13325222 | S35: =R35/R$49 -> 0.032834613 | T35: =I35/R35*$B$18 -> 43.331556
B36: Transportation | C36: Transportation | E36: per vehicle | F36: per FU
A37: 18124 | B37: transport, freight train | C37: =INDEX('Selected processes'!$E$5:$E$97, MATCH('Carbon footprint calculator'!$A37,'Selected processes'!$D$5:$D$97,0)) -> market group for transport, freight train | D37: =INDEX('Selected processes'!$F$5:$F$97, MATCH('Carbon footprint calculator'!$A37,'Selected processes'!$D$5:$D$97,0)) -> RER | E37: 556.5 | F37: =E37/$C$20 -> 0.00371 | G37: =INDEX('Selected processes'!$H$5:$H$97, MATCH('Carbon footprint calculator'!$A37,'Selected processes'!$D$5:$D$97,0)) -> metric ton*km | H37: =INDEX('Selected processes'!$J$5:$J$97, MATCH('Carbon footprint calculator'!$A37,'Selected processes'!$D$5:$D$97,0)) -> 0.045728106 | I37: =H37*$F37 -> 0.00016965127 | J37: =I37/I$49 -> 0.00054622622 | K37: =INDEX('Selected processes'!$K$5:$K$97, MATCH('Carbon footprint calculator'!$A37,'Selected processes'!$D$5:$D$97,0)) -> 0.068157807 | L37: =K37*$F37 -> 0.00025286546 | M37: =L37/L$49 -> -0.00087957663 | N37: =INDEX('Selected processes'!$L$5:$L$97, MATCH('Carbon footprint calculator'!$A37,'Selected processes'!$D$5:$D$97,0)) -> 2.5241034e-10 | O37: =N37*$F37 -> 9.3644236e-13 | P37: =O37/O$49 -> 0.00061307617 | Q37: =INDEX('Selected processes'!$N$5:$N$97, MATCH('Carbon footprint calculator'!$A37,'Selected processes'!$D$5:$D$97,0)) -> 0.71319593 | R37: =Q37*$F37 -> 0.0026459569 | S37: =R37/R$49 -> 0.00065198891 | T37: =I37/R37*$B$18 -> 64.117172
A38: 18241 | B38: transport, freight, lorry 16-32 metric ton | C38: =INDEX('Selected processes'!$E$5:$E$97, MATCH('Carbon footprint calculator'!$A38,'Selected processes'!$D$5:$D$97,0)) -> market for transport, freight, lorry 16-32 metric ton, EURO4 | D38: =INDEX('Selected processes'!$F$5:$F$97, MATCH('Carbon footprint calculator'!$A38,'Selected processes'!$D$5:$D$97,0)) -> RoW | E38: 59.1 | F38: =E38/$C$20 -> 0.000394 | G38: =INDEX('Selected processes'!$H$5:$H$97, MATCH('Carbon footprint calculator'!$A38,'Selected processes'!$D$5:$D$97,0)) -> metric ton*km | H38: =INDEX('Selected processes'!$J$5:$J$97, MATCH('Carbon footprint calculator'!$A38,'Selected processes'!$D$5:$D$97,0)) -> 0.19079134 | I38: =H38*$F38 -> 7.517179e-05 | J38: =I38/I$49 -> 0.00024203062 | K38: =INDEX('Selected processes'!$K$5:$K$97, MATCH('Carbon footprint calculator'!$A38,'Selected processes'!$D$5:$D$97,0)) -> 0.20108682 | L38: =K38*$F38 -> 7.9228205e-05 | M38: =L38/L$49 -> -0.00027559034 | N38: =INDEX('Selected processes'!$L$5:$L$97, MATCH('Carbon footprint calculator'!$A38,'Selected processes'!$D$5:$D$97,0)) -> 8.7787947e-10 | O38: =N38*$F38 -> 3.4588451e-13 | P38: =O38/O$49 -> 0.00022644592 | Q38: =INDEX('Selected processes'!$N$5:$N$97, MATCH('Carbon footprint calculator'!$A38,'Selected processes'!$D$5:$D$97,0)) -> 2.8903577 | R38: =Q38*$F38 -> 0.0011388009 | S38: =R38/R$49 -> 0.00028061136 | T38: =I38/R38*$B$18 -> 66.009596
A39: 18438 | B39: transport, freight, sea, container ship | C39: =INDEX('Selected processes'!$E$5:$E$97, MATCH('Carbon footprint calculator'!$A39,'Selected processes'!$D$5:$D$97,0)) -> transport, freight, sea, container ship | D39: =INDEX('Selected processes'!$F$5:$F$97, MATCH('Carbon footprint calculator'!$A39,'Selected processes'!$D$5:$D$97,0)) -> GLO | E39: =(E23+SUM(E25:E32))*8000/1000 -> 11376.814 | F39: =E39/$C$20 -> 0.075845424 | G39: =INDEX('Selected processes'!$H$5:$H$97, MATCH('Carbon footprint calculator'!$A39,'Selected processes'!$D$5:$D$97,0)) -> metric ton*km | H39: =INDEX('Selected processes'!$J$5:$J$97, MATCH('Carbon footprint calculator'!$A39,'Selected processes'!$D$5:$D$97,0)) -> 0.010163513 | I39: =H39*$F39 -> 0.00077085596 | J39: =I39/I$49 -> 0.002481925 | K39: =INDEX('Selected processes'!$K$5:$K$97, MATCH('Carbon footprint calculator'!$A39,'Selected processes'!$D$5:$D$97,0)) -> 0.026445888 | L39: =K39*$F39 -> 0.0020057996 | M39: =L39/L$49 -> -0.0069770478 | N39: =INDEX('Selected processes'!$L$5:$L$97, MATCH('Carbon footprint calculator'!$A39,'Selected processes'!$D$5:$D$97,0)) -> 9.6094188e-11 | O39: =N39*$F39 -> 7.2883044e-12 | P39: =O39/O$49 -> 0.0047715545 | Q39: =INDEX('Selected processes'!$N$5:$N$97, MATCH('Carbon footprint calculator'!$A39,'Selected processes'!$D$5:$D$97,0)) -> 0.13313526 | R39: =Q39*$F39 -> 0.0100977 | S39: =R39/R$49 -> 0.0024881691 | T39: =I39/R39*$B$18 -> 76.339757
B40: Use phase | C40: Use phase | E40: per V-km | F40: per FU
A41: 100002 | B41: Health benefit from driving phys. Activivity | C41: =INDEX('Selected processes'!$E$5:$E$97, MATCH('Carbon footprint calculator'!$A41,'Selected processes'!$D$5:$D$97,0)) -> Driving a car | D41: =INDEX('Selected processes'!$F$5:$F$97, MATCH('Carbon footprint calculator'!$A41,'Selected processes'!$D$5:$D$97,0)) -> driving an automobile | E41: 1 | F41: 1 | G41: =INDEX('Selected processes'!$H$5:$H$97, MATCH('Carbon footprint calculator'!$A41,'Selected processes'!$D$5:$D$97,0)) -> km | H41: =INDEX('Selected processes'!$J$5:$J$97, MATCH('Carbon footprint calculator'!$A41,'Selected processes'!$D$5:$D$97,0)) -> 0 | I41: =H41*$F41 -> 0 | J41: =I41/I$49 -> 0 | K41: =INDEX('Selected processes'!$K$5:$K$97, MATCH('Carbon footprint calculator'!$A41,'Selected processes'!$D$5:$D$97,0)) -> -0.72627994 | L41: =K41*$F41 -> -0.72627994 | M41: =L41/L$49 -> 2.5263192 | N41: =INDEX('Selected processes'!$L$5:$L$97, MATCH('Carbon footprint calculator'!$A41,'Selected processes'!$D$5:$D$97,0)) -> 0 | O41: =N41*$F41 -> 0 | P41: =O41/O$49 -> 0 | Q41: =INDEX('Selected processes'!$N$5:$N$97, MATCH('Carbon footprint calculator'!$A41,'Selected processes'!$D$5:$D$97,0)) -> 0 | R41: =Q41*$F41 -> 0 | S41: =R41/R$49 -> 0 | T41: =I41/R41*$B$18 -> #DIV/0!
A42: 14137 | B42: Supply chain petrol, low-sulfur | C42: =INDEX('Selected processes'!$E$5:$E$97, MATCH('Carbon footprint calculator'!$A42,'Selected processes'!$D$5:$D$97,0)) -> market for petrol, low-sulfur | D42: =INDEX('Selected processes'!$F$5:$F$97, MATCH('Carbon footprint calculator'!$A42,'Selected processes'!$D$5:$D$97,0)) -> Europe without Switzerland | E42: 0.061904762 | F42: =E42 -> 0.061904762 | G42: =INDEX('Selected processes'!$H$5:$H$97, MATCH('Carbon footprint calculator'!$A42,'Selected processes'!$D$5:$D$97,0)) -> kg | H42: =INDEX('Selected processes'!$J$5:$J$97, MATCH('Carbon footprint calculator'!$A42,'Selected processes'!$D$5:$D$97,0)) -> 1.0179093 | I42: =H42*$F42 -> 0.06301343 | J42: =I42/I$49 -> 0.20288435 | K42: =INDEX('Selected processes'!$K$5:$K$97, MATCH('Carbon footprint calculator'!$A42,'Selected processes'!$D$5:$D$97,0)) -> 1.0613393 | L42: =K42*$F42 -> 0.065701956 | M42: =L42/L$49 -> -0.22854013 | N42: =INDEX('Selected processes'!$L$5:$L$97, MATCH('Carbon footprint calculator'!$A42,'Selected processes'!$D$5:$D$97,0)) -> 4.4865308e-09 | O42: =N42*$F42 -> 2.7773762e-10 | P42: =O42/O$49 -> 0.18183107 | Q42: =INDEX('Selected processes'!$N$5:$N$97, MATCH('Carbon footprint calculator'!$A42,'Selected processes'!$D$5:$D$97,0)) -> 56.767141 | R42: =Q42*$F42 -> 3.5141563 | S42: =R42/R$49 -> 0.86592149 | T42: =I42/R42*$B$18 -> 17.931311
A43: 100001 | B43: Direct combustion | C43: =INDEX('Selected processes'!$E$5:$E$97, MATCH('Carbon footprint calculator'!$A43,'Selected processes'!$D$5:$D$97,0)) -> Emissions & operation of vehicle | D43: =INDEX('Selected processes'!$F$5:$F$97, MATCH('Carbon footprint calculator'!$A43,'Selected processes'!$D$5:$D$97,0)) -> RER | E43: 0.061904762 | F43: =E43 -> 0.061904762 | G43: =INDEX('Selected processes'!$H$5:$H$97, MATCH('Carbon footprint calculator'!$A43,'Selected processes'!$D$5:$D$97,0)) -> kg petrol | H43: =INDEX('Selected processes'!$J$5:$J$97, MATCH('Carbon footprint calculator'!$A43,'Selected processes'!$D$5:$D$97,0)) -> 3.4252308 | I43: =H43*$F43 -> 0.2120381 | J43: =I43/I$49 -> 0.68269907 | K43: =INDEX('Selected processes'!$K$5:$K$97, MATCH('Carbon footprint calculator'!$A43,'Selected processes'!$D$5:$D$97,0)) -> 4.5694635 | L43: =K43*$F43 -> 0.28287155 | M43: =L43/L$49 -> -0.98395091 | N43: =INDEX('Selected processes'!$L$5:$L$97, MATCH('Carbon footprint calculator'!$A43,'Selected processes'!$D$5:$D$97,0)) -> 1.7432418e-08 | O43: =N43*$F43 -> 1.0791497e-09 | P43: =O43/O$49 -> 0.70650473 | Q43: =INDEX('Selected processes'!$N$5:$N$97, MATCH('Carbon footprint calculator'!$A43,'Selected processes'!$D$5:$D$97,0)) -> 0 | R43: =Q43*$F43 -> 0 | S43: =R43/R$49 -> 0 | T43: =I43/R43*$B$18 -> #DIV/0!
B44: Disposal | C44: Disposal | E44: per vehicle over lifespan | F44: per FU
A45: 19923 | B45: plastic mixture incineration | C45: =INDEX('Selected processes'!$E$5:$E$97, MATCH('Carbon footprint calculator'!$A45,'Selected processes'!$D$5:$D$97,0)) -> treatment of waste plastic, mixture, municipal incineration | D45: =INDEX('Selected processes'!$F$5:$F$97, MATCH('Carbon footprint calculator'!$A45,'Selected processes'!$D$5:$D$97,0)) -> CH | E45: =E28+E29 -> 221 | F45: =E45/$C$20 -> 0.0014733333 | G45: =INDEX('Selected processes'!$H$5:$H$97, MATCH('Carbon footprint calculator'!$A45,'Selected processes'!$D$5:$D$97,0)) -> kg | H45: =INDEX('Selected processes'!$J$5:$J$97, MATCH('Carbon footprint calculator'!$A45,'Selected processes'!$D$5:$D$97,0)) -> 2.3457342 | I45: =H45*$F45 -> 0.0034560484 | J45: =I45/I$49 -> 0.011127439 | K45: =INDEX('Selected processes'!$K$5:$K$97, MATCH('Carbon footprint calculator'!$A45,'Selected processes'!$D$5:$D$97,0)) -> 1.3115341 | L45: =K45*$F45 -> 0.001932327 | M45: =L45/L$49 -> -0.006721478 | N45: =INDEX('Selected processes'!$L$5:$L$97, MATCH('Carbon footprint calculator'!$A45,'Selected processes'!$D$5:$D$97,0)) -> 6.7933555e-09 | O45: =N45*$F45 -> 1.0008877e-11 | P45: =O45/O$49 -> 0.0065526768 | Q45: =INDEX('Selected processes'!$N$5:$N$97, MATCH('Carbon footprint calculator'!$A45,'Selected processes'!$D$5:$D$97,0)) -> 0.48721305 | R45: =Q45*$F45 -> 0.00071782723 | S45: =R45/R$49 -> 0.00017687944 | T45: =I45/R45*$B$18 -> 4814.5964
...

Sheet Life cycle costing
A3: Vehicle lifetime before resale | B3: 10
A4: Vehicle lifespan (km/vehicle) | B4: 150000 | F4: Costs | J4: Costs
A5: Transportation by Gas Vehicle FU= 1 vehicle km Life Cycle stage (150,000 km lifespan) | C5: Quantity original unit | D5: Quantity per FU | E5: Unit | F5: price/Unit [Euro/Unit] | G5: Cost per FU [Euro/V-km] | H5: fraction costs | J5: Euro/V-km | K5: Petrol Vehicle | L5: Electric Vehicle | M5: Electric Vehicle - Wind | N5: Electric Vehicle - Photovoltaic | O5: Electric Vehicle - hard coal
A6: Purchase | B6: Cost relevant distance | C6: per vehicle over lifespan | D6: per FU | J6: Purchase | K6: =SUM(G7:G8) -> 0.21333333 | L6: =SUM(G29:G30) -> 0.22222222 | M6: =$L6 -> 0.22222222 | N6: =$L6 -> 0.22222222 | O6: =$L6 -> 0.22222222
A7: 1 vehicle | B7: =$B$4 -> 150000 | C7: 1 | D7: =C7/B7 -> 6.6666667e-06 | E7: p | F7: 30000 | G7: =F7*D7 -> 0.2 | H7: =G7/G$20 -> 0.44349293 | J7: Fixed annual costs | K7: =SUM(G10:G11) -> 0.046666667 | L7: =SUM(G32:G33) -> 0.035555556 | M7: =$L7 -> 0.035555556 | N7: =$L7 -> 0.035555556 | O7: =$L7 -> 0.035555556
A8: Tax on vehicle at purchase | B8: =$B$4 -> 150000 | C8: 1 | D8: =C8/B8 -> 6.6666667e-06 | E8: p | F8: 2000 | G8: =F8*D8 -> 0.013333333 | H8: =G8/G$20 -> 0.029566195 | J8: Variable cost maintenance | K8: =SUM(G13:G14) -> 0.105 | L8: =SUM(G35:G36) -> 0.06 | M8: =$L8 -> 0.06 | N8: =$L8 -> 0.06 | O8: =$L8 -> 0.06
A9: Fixed annual costs | B9: km/yr | C9: per year | D9: per FU | J9: Variable cost Fuel - Use phase | K9: =G16 -> 0.10596548 | L9: =G38 -> 0.052
A10: Insurance per year | B10: =B4/B3 -> 15000 | C10: 1 | D10: =C10/B10 -> 6.6666667e-05 | E10: p | F10: 500 | G10: =F10*$D10 -> 0.033333333 | H10: =G10/G$20 -> 0.073915488 | J10: Resale | K10: =G18 -> -0.02 | L10: =G40 -> -0.013333333 | M10: =$L10 -> -0.013333333
A11: Taxes for immatriculation per year | B11: =B4/B3 -> 15000 | C11: 1 | D11: =C11/B11 -> 6.6666667e-05 | E11: p | F11: 200 | G11: =F11*$D11 -> 0.013333333 | H11: =G11/G$20 -> 0.029566195 | J11: Electric charging - wind | M11: =$L$8*M$17 -> 0.036
A12: Variabl cost maintenance | B12: km until change | D12: per FU | J12: Electric charging - photovoltaic | N12: =$L$8*N$17 -> 0.054
A13: maintenance per 10000km | B13: 10000 | C13: 1 | D13: =C13/B13 -> 0.0001 | E13: p | F13: 750 | G13: =F13*$D13 -> 0.075 | H13: =G13/G$20 -> 0.16630985 | J13: Electric charging - hard coal | O13: =$L$8*O$17 -> 0.078
A14: Tires change every 20000 km | B14: 20000 | C14: 4 | D14: =C14/B14 -> 0.0002 | E14: p | F14: 150 | G14: =F14*$D14 -> 0.03 | H14: =G14/G$20 -> 0.066523939 | J14: Total | K14: =SUM(K6:K10) -> 0.45096548 | L14: =SUM(L6:L10) -> 0.35644444 | M14: =SUM(M6:M10) -> 0.30444444 | N14: =SUM(N6:N10) -> 0.31777778 | O14: =SUM(O6:O10) -> 0.31777778
A15: Variable cost Fuel - Use phase | C15: per V-km | D15: per FU
A16: Supply chain petrol, low-sulfur | B16: 1 | C16: =0.0619047619047619*0.835 -> 0.051690476 | D16: =C16/B16 -> 0.051690476 | E16: L | F16: 2.05 | G16: =F16*$D16 -> 0.10596548 | H16: =G16/G$20 -> 0.2349747
A17: Resale value - end of life | C17: per vehicle over lifespan | D17: per FU | J17: relative price by soure | K17: GUESS so far | L17: 1 | M17: 0.6 | N17: 0.9 | O17: 1.3
A18: 1 vehicle | B18: =$B$4 -> 150000 | C18: -1 | D18: =C18/B18 -> -6.6666667e-06 | E18: p | F18: 3000 | G18: =F18*$D18 -> -0.02 | H18: =G18/G$20 -> -0.044349293
A19: Total | D19: per FU
A20: Total | B20: Euro/V-km | C20: - | E20: - | G20: =SUM(G7:G18) -> 0.45096548 | H20: =G20/G$20 -> 1
A21: Conversion rate | B21: Kr/Euro | C21: 7.44 | D21: Total DKK | G21: Kr/V-km | H21: =SUM(H7:H17) -> 1.0443493
A22: Total | B22: DKK/V-km | G22: =G20*$C$21 -> 3.3551831
A25: Vehicle lifetime before resale | B25: 10
A26: Vehicle lifespan (km/vehicle) | B26: 225000 | F26: Costs
A27: Transportation by Electric Vehicle FU= 1 vehicle km Life Cycle stage (225000 km lifespan) | C27: Quantity original unit | D27: Quantity per FU | E27: Unit | F27: price/Unit [Euro/Unit] | G27: Cost per FU [Euro/V-km] | H27: fraction costs
A28: Purchase | B28: Cost relevant distance | C28: per vehicle over lifespan | D28: per FU
A29: 1 vehicle | B29: =$B$26 -> 225000 | C29: 1 | D29: =C29/B29 -> 4.4444444e-06 | E29: p | F29: 50000 | G29: =F29*D29 -> 0.22222222 | H29: =G29/G$42 -> 0.6234414
A30: Tax on vehicle at purchase | B30: =$B$26 -> 225000 | C30: 1 | D30: =C30/B30 -> 4.4444444e-06 | E30: p | F30: 0 | G30: =F30*D30 -> 0 | H30: =G30/G$42 -> 0
A31: Fixed annual costs | C31: annual purchase | D31: per FU
A32: Insurance per year | B32: =$B$26/$B$25 -> 22500 | C32: 1 | D32: =C32/B32 -> 4.4444444e-05 | E32: p | F32: 700 | G32: =F32*$D32 -> 0.031111111 | H32: =G32/G$42 -> 0.087281796
A33: Taxes for immatriculation per year | B33: =$B$26/$B$25 -> 22500 | C33: 1 | D33: =C33/B33 -> 4.4444444e-05 | E33: p | F33: 100 | G33: =F33*$D33 -> 0.0044444444 | H33: =G33/G$42 -> 0.012468828
A34: Variable cost maintenance | D34: per FU
A35: maintenance per 10000km | B35: 10000 | C35: 1 | D35: =C35/B35 -> 0.0001 | E35: p | F35: 300 | G35: =F35*$D35 -> 0.03 | H35: =G35/G$42 -> 0.084164589
A36: Tires change every 20000 km | B36: 20000 | C36: 4 | D36: =C36/B36 -> 0.0002 | E36: p | F36: 150 | G36: =F36*$D36 -> 0.03 | H36: =G36/G$42 -> 0.084164589
A37: Variable cost Fuel - Use phase | C37: per V-km | D37: per FU
A38: Electricity consumption | B38: 1 | C38: 0.26 | D38: =C38/B38 -> 0.26 | E38: L | F38: 0.2 | G38: =F38*$D38 -> 0.052 | H38: =G38/G$42 -> 0.14588529
A39: Resale value - end of life | C39: per vehicle over lifespan | D39: per FU
A40: 1 vehicle | B40: =$B$26 -> 225000 | C40: -1 | D40: =C40/B40 -> -4.4444444e-06 | E40: p | F40: 3000 | G40: =F40*$D40 -> -0.013333333 | H40: =G40/G$42 -> -0.037406484
A41: Total | D41: per FU
A42: Total | C42: - | E42: - | G42: =SUM(G29:G40) -> 0.35644444 | H42: =G42/G$42 -> 1
G43: Kr/V-km | H43: =SUM(H29:H39) -> 1.0374065
G44: =G42*$C$21 -> 2.6519467
...

Sheet Absolute sustainability
A1: Absolute sustainability assessment for carbon footprint per FU | C1: Vehicule case study
C2: World population on 15.11.2022
A3: Determination of Absolute sustainability: climate change | B3: Absolute radiative forcing | C3: Values
A5: Planetary Boundary (PB) - radiative forcing | B5: W/m2 | C5: 1
A6: CF | B6: W/m2/ (kgCO2e/yr) | C6: 3.53e-13
A7: Planetary Boundary (PB) - climate change in CO2e | B7: kgCO2e/yr | C7: =C5/C6 -> 2.8328612e+12
A9: World population | B9: pers | C9: 8000000000
A10: Share of PB per person | B10: 1/pers | C10: =1/C9 -> 1.25e-10
A11: Planetary Boundary (PB) - CO2e impacts per person | B11: kgCO2e/pers/yr | C11: =C7*C10 -> 354.10765
A12: Economic allocation | D12: Grand fathering
A13: Country (see ISO code in "World carbon footprint" tab) | B13: Denmark | C13: DNK
A14: GDP Denmark PPP Kr./cap/yr | B14: CUR/cap/yr | C14: =INDEX('World carbon footprint'!$N$16:$N$131,MATCH('Absolute sustainability'!$C$13,'World carbon footprint'!$C$16:$C$131,0)) -> 361868.04 | D14: Total present consumption-based impact DK | E14: kgCO2e/pers/yr | F14: =INDEX('World carbon footprint'!$K$16:$K$131,MATCH('Absolute sustainability'!$C$13,'World carbon footprint'!$C$16:$C$131,0))*'Carbon footprint calculator'!$B$17 -> 10287.356
A15: Life cycle cost per FU (per V-km), module 5 | B15: CUR/V-km gasoline car | C15: ='Life cycle costing'!G22 -> 3.3551831
A16: Share of total boundary attributable to 1 vehicle km | B16: - | C16: =C15/C14 -> 9.2718415e-06 | D16: Reduction factor to reach PB | E16: - | F16: =F14/C11 -> 29.051493
A18: Sustainable boundary assigned to FU of 1 V-km | B18: kgCO2e/V-km | C18: =C16*C11 -> 0.00328323 | D18: Sustainable boundary assigned to 1 V-km | E18: kgCO2e/V-km | F18: =C21/F16 -> 0.010690946
A20: Impact | C20: Reference scenario Gas Vehicle | D20: Electric Vehicle - EU average | E20: Electric Vehicle - Wind | F20: Electric Vehicle - Photovoltaic | G20: Electric Vehicle - Hard coal | H20: E-bike - EU average | I20: Bike
A21: Carbon footprint impact per V-km, module 3 | B21: kgCO2e/V-km | C21: ='Carbon footprint calculator'!W15 -> 0.31058794 | D21: ='Carbon footprint calculator'!Y15 -> 0.14925681 | E21: ='Carbon footprint calculator'!Z15 -> 0.053008148 | F21: ='Carbon footprint calculator'!AA15 -> 0.070038846 | G21: ='Carbon footprint calculator'!X15 -> 0.33401216 | H21: ='Carbon footprint calculator'!AB15 -> 0.00792545 | I21: ='Carbon footprint calculator'!AC15 -> 0.0051664754
A22: Sustainable boundary target per V-km, economic allocation | C22: =C18 -> 0.00328323
A23: Sustainable boundary target per V-km, grand fathering | C23: =F18 -> 0.010690946
A25: Absolute Sust. Ratio & exceedance economic allocation | C25: =C21/$C$18 -> 94.598288 | D25: =D21/$C$18 -> 45.460357 | E25: =E21/$C$18 -> 16.145122 | F25: =F21/$C$18 -> 21.3323 | G25: =G21/$C$18 -> 101.73279 | H25: =H21/$C$18 -> 2.4139186 | I25: =I21/$C$18 -> 1.5735954
A26: Absolute Sust. Ratio & exceedance grand fathering | C26: =C21/$F$18 -> 29.051493 | D26: =D21/$F$18 -> 13.961048 | E26: =E21/$F$18 -> 4.9582281 | F26: =F21/$F$18 -> 6.55123 | G26: =G21/$F$18 -> 31.242527 | H26: =H21/$F$18 -> 0.74132356 | I26: =I21/$F$18 -> 0.48325709
A28: Comments: | B28: For the electric bike, it would reach the absolute sustainability level if the bike production would be reduced by e.g. electrification

Sheet Selected processes
I1: Method | J1: IPCC 2021 | K1: ReCiPe 2016 v1.03, endpoint (H) | L1: ReCiPe 2016 v1.03, endpoint (H) | M1: ReCiPe 2016 v1.03, endpoint (H) | N1: Cumulative Energy Demand (CED) | O1: selected LCI results | P1: Ratio CO2 fossil/non ren. cum. energy demand
D2: Conversion factors | E2: kg_to_g | F2: g/kg | G2: 1000 | I2: Category | J2: climate change | K2: total: human health | L2: total: ecosystem quality | M2: total: natural resources | N2: energy resources: non-renewable | O2: air | P2: CO2 fossil/total non renewable energy
C3: =INDEX('Ecoinvent data'!$B$5:$B$21242, MATCH('Selected processes'!D3,'Ecoinvent data'!$D$5:$D$21242,0)) -> #N/A | I3: Indicator | J3: global warming potential (GWP100) | K3: human health | L3: ecosystem quality | M3: natural resources | N3: energy content (HHV) | O3: CO2, fossil | P3: Check combustion included
D4: Process # | E4: Activity Name | F4: Geography | G4: Reference Product Name | H4: Reference Product Unit | I4: Reference Product Amount | J4: kg CO2-Eq | K4: min.lost | L4: species.yr | M4: USD 2013 | N4: MJ-Eq | O4: kg | P4: gCO2/MJ
A5: alkyd paint production, white, solvent-based, product in 60% solution stateRERalkyd paint, white, without solvent, in 60% solution statekg | B5: 17446 | C5: =INDEX('Ecoinvent data'!$B$5:$B$21242, MATCH('Selected processes'!D5,'Ecoinvent data'!$D$5:$D$21242,0)) -> 17299 | D5: 17299 | E5: steel production, low-alloyed, hot rolled | F5: RER | G5: =INDEX('Ecoinvent data'!G$5:G$21242,MATCH($D5,'Ecoinvent data'!$D$5:$D$21242,0)) -> steel, low-alloyed, hot rolled | H5: =INDEX('Ecoinvent data'!H$5:H$21242,MATCH($D5,'Ecoinvent data'!$D$5:$D$21242,0)) -> kg | I5: =INDEX('Ecoinvent data'!I$5:I$21242,MATCH($D5,'Ecoinvent data'!$D$5:$D$21242,0)) -> 1 | J5: =INDEX('Ecoinvent data'!J$5:J$21242,MATCH($D5,'Ecoinvent data'!$D$5:$D$21242,0)) -> 2.1807172 | K5: =INDEX('Ecoinvent data'!K$5:K$21242,MATCH($D5,'Ecoinvent data'!$D$5:$D$21242,0)) -> 7.9963289 | L5: =INDEX('Ecoinvent data'!L$5:L$21242,MATCH($D5,'Ecoinvent data'!$D$5:$D$21242,0)) -> 9.7808189e-09 | M5: =INDEX('Ecoinvent data'!M$5:M$21242,MATCH($D5,'Ecoinvent data'!$D$5:$D$21242,0)) -> 0.24593889 | N5: =INDEX('Ecoinvent data'!N$5:N$21242,MATCH($D5,'Ecoinvent data'!$D$5:$D$21242,0)) -> 25.556652 | ... P5: =INDEX('Ecoinvent data'!P$5:P$21242,MATCH($D5,'Ecoinvent data'!$D$5:$D$21242,0)) -> 76.062947
A6: aluminium production, primary, ingotRoWaluminium, primary, ingotkg | B6: 17078 | C6: =INDEX('Ecoinvent data'!$B$5:$B$21242, MATCH('Selected processes'!D6,'Ecoinvent data'!$D$5:$D$21242,0)) -> 16619 | D6: 16619 | E6: =INDEX('Ecoinvent data'!E$5:E$21242,MATCH($D6,'Ecoinvent data'!$D$5:$D$21242,0)) -> sheet rolling, steel | F6: =INDEX('Ecoinvent data'!F$5:F$21242,MATCH($D6,'Ecoinvent data'!$D$5:$D$21242,0)) -> RER | G6: =INDEX('Ecoinvent data'!G$5:G$21242,MATCH($D6,'Ecoinvent data'!$D$5:$D$21242,0)) -> sheet rolling, steel | H6: =INDEX('Ecoinvent data'!H$5:H$21242,MATCH($D6,'Ecoinvent data'!$D$5:$D$21242,0)) -> kg | I6: =INDEX('Ecoinvent data'!I$5:I$21242,MATCH($D6,'Ecoinvent data'!$D$5:$D$21242,0)) -> 1 | J6: =INDEX('Ecoinvent data'!J$5:J$21242,MATCH($D6,'Ecoinvent data'!$D$5:$D$21242,0)) -> 0.31200613 | K6: =INDEX('Ecoinvent data'!K$5:K$21242,MATCH($D6,'Ecoinvent data'!$D$5:$D$21242,0)) -> 0.73372079 | L6: =INDEX('Ecoinvent data'!L$5:L$21242,MATCH($D6,'Ecoinvent data'!$D$5:$D$21242,0)) -> 1.3767966e-09 | ... P6: =INDEX('Ecoinvent data'!P$5:P$21242,MATCH($D6,'Ecoinvent data'!$D$5:$D$21242,0)) -> 56.58959
A7: chromium oxide production, flakesRoWchromium oxide, flakeskg | B7: 323 | C7: =INDEX('Ecoinvent data'!$B$5:$B$21242, MATCH('Selected processes'!D7,'Ecoinvent data'!$D$5:$D$21242,0)) -> 458 | D7: 458 | E7: aluminium production, primary, ingot | F7: IAI Area, EU27 & EFTA | G7: =INDEX('Ecoinvent data'!G$5:G$21242,MATCH($D7,'Ecoinvent data'!$D$5:$D$21242,0)) -> aluminium, primary, ingot | H7: =INDEX('Ecoinvent data'!H$5:H$21242,MATCH($D7,'Ecoinvent data'!$D$5:$D$21242,0)) -> kg | I7: =INDEX('Ecoinvent data'!I$5:I$21242,MATCH($D7,'Ecoinvent data'!$D$5:$D$21242,0)) -> 1 | J7: =INDEX('Ecoinvent data'!J$5:J$21242,MATCH($D7,'Ecoinvent data'!$D$5:$D$21242,0)) -> 7.209838 | K7: =INDEX('Ecoinvent data'!K$5:K$21242,MATCH($D7,'Ecoinvent data'!$D$5:$D$21242,0)) -> 13.333429 | L7: =INDEX('Ecoinvent data'!L$5:L$21242,MATCH($D7,'Ecoinvent data'!$D$5:$D$21242,0)) -> 3.2653298e-08 | M7: =INDEX('Ecoinvent data'!M$5:M$21242,MATCH($D7,'Ecoinvent data'!$D$5:$D$21242,0)) -> 0.57610667 | N7: =INDEX('Ecoinvent data'!N$5:N$21242,MATCH($D7,'Ecoinvent data'!$D$5:$D$21242,0)) -> 115.04046 | ... P7: =INDEX('Ecoinvent data'!P$5:P$21242,MATCH($D7,'Ecoinvent data'!$D$5:$D$21242,0)) -> 55.834159
A8: sheet rolling, copperRERsheet rolling, copperkg | B8: 17076 | C8: =INDEX('Ecoinvent data'!$B$5:$B$21242, MATCH('Selected processes'!D8,'Ecoinvent data'!$D$5:$D$21242,0)) -> 16616 | D8: 16616 | E8: =INDEX('Ecoinvent data'!E$5:E$21242,MATCH($D8,'Ecoinvent data'!$D$5:$D$21242,0)) -> sheet rolling, copper | F8: =INDEX('Ecoinvent data'!F$5:F$21242,MATCH($D8,'Ecoinvent data'!$D$5:$D$21242,0)) -> RER | G8: =INDEX('Ecoinvent data'!G$5:G$21242,MATCH($D8,'Ecoinvent data'!$D$5:$D$21242,0)) -> sheet rolling, copper | H8: =INDEX('Ecoinvent data'!H$5:H$21242,MATCH($D8,'Ecoinvent data'!$D$5:$D$21242,0)) -> kg | I8: =INDEX('Ecoinvent data'!I$5:I$21242,MATCH($D8,'Ecoinvent data'!$D$5:$D$21242,0)) -> 1 | J8: =INDEX('Ecoinvent data'!J$5:J$21242,MATCH($D8,'Ecoinvent data'!$D$5:$D$21242,0)) -> 0.48163006 | K8: =INDEX('Ecoinvent data'!K$5:K$21242,MATCH($D8,'Ecoinvent data'!$D$5:$D$21242,0)) -> 4.9624408 | L8: =INDEX('Ecoinvent data'!L$5:L$21242,MATCH($D8,'Ecoinvent data'!$D$5:$D$21242,0)) -> 9.7940056e-09 | ... P8: =INDEX('Ecoinvent data'!P$5:P$21242,MATCH($D8,'Ecoinvent data'!$D$5:$D$21242,0)) -> 58.647233
A9: electronics production, for control unitsRERelectronics, for control unitskg | B9: 16311 | C9: =INDEX('Ecoinvent data'!$B$5:$B$21242, MATCH('Selected processes'!D9,'Ecoinvent data'!$D$5:$D$21242,0)) -> 12456 | D9: 12456 | E9: =INDEX('Ecoinvent data'!E$5:E$21242,MATCH($D9,'Ecoinvent data'!$D$5:$D$21242,0)) -> platinum to generic market for metal catalyst for catalytic converter | F9: =INDEX('Ecoinvent data'!F$5:F$21242,MATCH($D9,'Ecoinvent data'!$D$5:$D$21242,0)) -> GLO | G9: =INDEX('Ecoinvent data'!G$5:G$21242,MATCH($D9,'Ecoinvent data'!$D$5:$D$21242,0)) -> metal catalyst for catalytic converter | H9: =INDEX('Ecoinvent data'!H$5:H$21242,MATCH($D9,'Ecoinvent data'!$D$5:$D$21242,0)) -> kg | I9: =INDEX('Ecoinvent data'!I$5:I$21242,MATCH($D9,'Ecoinvent data'!$D$5:$D$21242,0)) -> 1 | J9: =INDEX('Ecoinvent data'!J$5:J$21242,MATCH($D9,'Ecoinvent data'!$D$5:$D$21242,0)) -> 69669.936 | K9: =INDEX('Ecoinvent data'!K$5:K$21242,MATCH($D9,'Ecoinvent data'!$D$5:$D$21242,0)) -> 571917.51 | L9: =INDEX('Ecoinvent data'!L$5:L$21242,MATCH($D9,'Ecoinvent data'!$D$5:$D$21242,0)) -> 0.0011984346 | ... P9: =INDEX('Ecoinvent data'!P$5:P$21242,MATCH($D9,'Ecoinvent data'!$D$5:$D$21242,0)) -> 57.364786
A10: ethylene production, averageRERethylenekg | B10: 12104 | C10: =INDEX('Ecoinvent data'!$B$5:$B$21242, MATCH('Selected processes'!D10,'Ecoinvent data'!$D$5:$D$21242,0)) -> 14632 | D10: 14632 | E10: =INDEX('Ecoinvent data'!E$5:E$21242,MATCH($D10,'Ecoinvent data'!$D$5:$D$21242,0)) -> market for polyethylene, high density, granulate | F10: =INDEX('Ecoinvent data'!F$5:F$21242,MATCH($D10,'Ecoinvent data'!$D$5:$D$21242,0)) -> GLO | G10: =INDEX('Ecoinvent data'!G$5:G$21242,MATCH($D10,'Ecoinvent data'!$D$5:$D$21242,0)) -> polyethylene, high density, granulate | H10: =INDEX('Ecoinvent data'!H$5:H$21242,MATCH($D10,'Ecoinvent data'!$D$5:$D$21242,0)) -> kg | I10: =INDEX('Ecoinvent data'!I$5:I$21242,MATCH($D10,'Ecoinvent data'!$D$5:$D$21242,0)) -> 1 | J10: =INDEX('Ecoinvent data'!J$5:J$21242,MATCH($D10,'Ecoinvent data'!$D$5:$D$21242,0)) -> 2.3276288 | K10: =INDEX('Ecoinvent data'!K$5:K$21242,MATCH($D10,'Ecoinvent data'!$D$5:$D$21242,0)) -> 2.3488561 | L10: =INDEX('Ecoinvent data'!L$5:L$21242,MATCH($D10,'Ecoinvent data'!$D$5:$D$21242,0)) -> 9.3798954e-09 | ... P10: =INDEX('Ecoinvent data'!P$5:P$21242,MATCH($D10,'Ecoinvent data'!$D$5:$D$21242,0)) -> 23.819736
A11: ethylene glycol productionRERethylene glycolkg | B11: 5070 | C11: =INDEX('Ecoinvent data'!$B$5:$B$21242, MATCH('Selected processes'!D11,'Ecoinvent data'!$D$5:$D$21242,0)) -> 7364 | D11: 7364 | E11: =INDEX('Ecoinvent data'!E$5:E$21242,MATCH($D11,'Ecoinvent data'!$D$5:$D$21242,0)) -> electronics production, for control units | F11: =INDEX('Ecoinvent data'!F$5:F$21242,MATCH($D11,'Ecoinvent data'!$D$5:$D$21242,0)) -> RER | G11: =INDEX('Ecoinvent data'!G$5:G$21242,MATCH($D11,'Ecoinvent data'!$D$5:$D$21242,0)) -> electronics, for control units | H11: =INDEX('Ecoinvent data'!H$5:H$21242,MATCH($D11,'Ecoinvent data'!$D$5:$D$21242,0)) -> kg | I11: =INDEX('Ecoinvent data'!I$5:I$21242,MATCH($D11,'Ecoinvent data'!$D$5:$D$21242,0)) -> 1 | J11: =INDEX('Ecoinvent data'!J$5:J$21242,MATCH($D11,'Ecoinvent data'!$D$5:$D$21242,0)) -> 31.86483 | K11: =INDEX('Ecoinvent data'!K$5:K$21242,MATCH($D11,'Ecoinvent data'!$D$5:$D$21242,0)) -> 91.052321 | L11: =INDEX('Ecoinvent data'!L$5:L$21242,MATCH($D11,'Ecoinvent data'!$D$5:$D$21242,0)) -> 2.0683158e-07 | ... P11: =INDEX('Ecoinvent data'!P$5:P$21242,MATCH($D11,'Ecoinvent data'!$D$5:$D$21242,0)) -> 61.755144
A12: market for flat glass, uncoatedRoWflat glass, uncoatedkg | B12: 5253 | C12: =INDEX('Ecoinvent data'!$B$5:$B$21242, MATCH('Selected processes'!D12,'Ecoinvent data'!$D$5:$D$21242,0)) -> 7587 | D12: 7587 | E12: =INDEX('Ecoinvent data'!E$5:E$21242,MATCH($D12,'Ecoinvent data'!$D$5:$D$21242,0)) -> ethylene production, average | F12: =INDEX('Ecoinvent data'!F$5:F$21242,MATCH($D12,'Ecoinvent data'!$D$5:$D$21242,0)) -> RER | G12: =INDEX('Ecoinvent data'!G$5:G$21242,MATCH($D12,'Ecoinvent data'!$D$5:$D$21242,0)) -> ethylene | H12: =INDEX('Ecoinvent data'!H$5:H$21242,MATCH($D12,'Ecoinvent data'!$D$5:$D$21242,0)) -> kg | I12: =INDEX('Ecoinvent data'!I$5:I$21242,MATCH($D12,'Ecoinvent data'!$D$5:$D$21242,0)) -> 1 | J12: =INDEX('Ecoinvent data'!J$5:J$21242,MATCH($D12,'Ecoinvent data'!$D$5:$D$21242,0)) -> 1.4469179 | K12: =INDEX('Ecoinvent data'!K$5:K$21242,MATCH($D12,'Ecoinvent data'!$D$5:$D$21242,0)) -> 1.1204239 | L12: =INDEX('Ecoinvent data'!L$5:L$21242,MATCH($D12,'Ecoinvent data'!$D$5:$D$21242,0)) -> 5.2741423e-09 | ... P12: =INDEX('Ecoinvent data'!P$5:P$21242,MATCH($D12,'Ecoinvent data'!$D$5:$D$21242,0)) -> 16.638073
A13: market for heat, district or industrial, natural gasRoWheat, district or industrial, natural gasMJ | B13: 17736 | C13: =INDEX('Ecoinvent data'!$B$5:$B$21242, MATCH('Selected processes'!D13,'Ecoinvent data'!$D$5:$D$21242,0)) -> 17773 | D13: 17773 | E13: =INDEX('Ecoinvent data'!E$5:E$21242,MATCH($D13,'Ecoinvent data'!$D$5:$D$21242,0)) -> tap water production, conventional treatment | F13: =INDEX('Ecoinvent data'!F$5:F$21242,MATCH($D13,'Ecoinvent data'!$D$5:$D$21242,0)) -> RoW | G13: =INDEX('Ecoinvent data'!G$5:G$21242,MATCH($D13,'Ecoinvent data'!$D$5:$D$21242,0)) -> tap water | H13: =INDEX('Ecoinvent data'!H$5:H$21242,MATCH($D13,'Ecoinvent data'!$D$5:$D$21242,0)) -> kg | I13: =INDEX('Ecoinvent data'!I$5:I$21242,MATCH($D13,'Ecoinvent data'!$D$5:$D$21242,0)) -> 1 | J13: =INDEX('Ecoinvent data'!J$5:J$21242,MATCH($D13,'Ecoinvent data'!$D$5:$D$21242,0)) -> 0.00043545824 | K13: =INDEX('Ecoinvent data'!K$5:K$21242,MATCH($D13,'Ecoinvent data'!$D$5:$D$21242,0)) -> 0.00063383807 | L13: =INDEX('Ecoinvent data'!L$5:L$21242,MATCH($D13,'Ecoinvent data'!$D$5:$D$21242,0)) -> 1.9288846e-12 | ... P13: =INDEX('Ecoinvent data'!P$5:P$21242,MATCH($D13,'Ecoinvent data'!$D$5:$D$21242,0)) -> 68.243499
A14: market for leadGLOleadkg | B14: 6843 | C14: =INDEX('Ecoinvent data'!$B$5:$B$21242, MATCH('Selected processes'!D14,'Ecoinvent data'!$D$5:$D$21242,0)) -> 9148 | D14: 9148 | E14: =INDEX('Ecoinvent data'!E$5:E$21242,MATCH($D14,'Ecoinvent data'!$D$5:$D$21242,0)) -> heat production, natural gas, at industrial furnace >100kW | F14: =INDEX('Ecoinvent data'!F$5:F$21242,MATCH($D14,'Ecoinvent data'!$D$5:$D$21242,0)) -> Europe without Switzerland | G14: =INDEX('Ecoinvent data'!G$5:G$21242,MATCH($D14,'Ecoinvent data'!$D$5:$D$21242,0)) -> heat, district or industrial, natural gas | H14: =INDEX('Ecoinvent data'!H$5:H$21242,MATCH($D14,'Ecoinvent data'!$D$5:$D$21242,0)) -> MJ | I14: =INDEX('Ecoinvent data'!I$5:I$21242,MATCH($D14,'Ecoinvent data'!$D$5:$D$21242,0)) -> 1 | J14: =INDEX('Ecoinvent data'!J$5:J$21242,MATCH($D14,'Ecoinvent data'!$D$5:$D$21242,0)) -> 0.075656104 | K14: =INDEX('Ecoinvent data'!K$5:K$21242,MATCH($D14,'Ecoinvent data'!$D$5:$D$21242,0)) -> 0.044167738 | L14: =INDEX('Ecoinvent data'!L$5:L$21242,MATCH($D14,'Ecoinvent data'!$D$5:$D$21242,0)) -> 2.338698e-10 | ... P14: =INDEX('Ecoinvent data'!P$5:P$21242,MATCH($D14,'Ecoinvent data'!$D$5:$D$21242,0)) -> 53.883249
A15: light fuel oil, burned in industrial furnace 1MW, non-modulatingRERLight fuel oil, burned in furnace 1MW of greenhouse/MJMJ | B15: 14708 | C15: =INDEX('Ecoinvent data'!$B$5:$B$21242, MATCH('Selected processes'!D15,'Ecoinvent data'!$D$5:$D$21242,0)) -> 7235 | D15: 7235 | E15: market group for electricity, medium voltage | F15: UCTE | G15: =INDEX('Ecoinvent data'!G$5:G$21242,MATCH($D15,'Ecoinvent data'!$D$5:$D$21242,0)) -> electricity, medium voltage | H15: =INDEX('Ecoinvent data'!H$5:H$21242,MATCH($D15,'Ecoinvent data'!$D$5:$D$21242,0)) -> kWh | I15: =INDEX('Ecoinvent data'!I$5:I$21242,MATCH($D15,'Ecoinvent data'!$D$5:$D$21242,0)) -> 1 | J15: =INDEX('Ecoinvent data'!J$5:J$21242,MATCH($D15,'Ecoinvent data'!$D$5:$D$21242,0)) -> 0.38493508 | K15: =INDEX('Ecoinvent data'!K$5:K$21242,MATCH($D15,'Ecoinvent data'!$D$5:$D$21242,0)) -> 0.48931866 | L15: =INDEX('Ecoinvent data'!L$5:L$21242,MATCH($D15,'Ecoinvent data'!$D$5:$D$21242,0)) -> 1.8304805e-09 | M15: =INDEX('Ecoinvent data'!M$5:M$21242,MATCH($D15,'Ecoinvent data'!$D$5:$D$21242,0)) -> 0.019620494 | N15: =INDEX('Ecoinvent data'!N$5:N$21242,MATCH($D15,'Ecoinvent data'!$D$5:$D$21242,0)) -> 8.8834816 | ... P15: =INDEX('Ecoinvent data'!P$5:P$21242,MATCH($D15,'Ecoinvent data'!$D$5:$D$21242,0)) -> 39.707089
